Traceback (most recent call last):
  File "C:\Users\zengo\AppData\Local\Programs\Python\Python311\Lib\site-packages\jupyter_cache\executors\utils.py", line 58, in single_nb_execution
    executenb(
  File "C:\Users\zengo\AppData\Local\Programs\Python\Python311\Lib\site-packages\nbclient\client.py", line 1305, in execute
    return NotebookClient(nb=nb, resources=resources, km=km, **kwargs).execute()
           ^^^^^^^^^^^^^^^^^^^^^^^^^^^^^^^^^^^^^^^^^^^^^^^^^^^^^^^^^^^^^^^^^^^^^
  File "C:\Users\zengo\AppData\Local\Programs\Python\Python311\Lib\site-packages\jupyter_core\utils\__init__.py", line 166, in wrapped
    return loop.run_until_complete(inner)
           ^^^^^^^^^^^^^^^^^^^^^^^^^^^^^^
  File "C:\Users\zengo\AppData\Local\Programs\Python\Python311\Lib\asyncio\base_events.py", line 653, in run_until_complete
    return future.result()
           ^^^^^^^^^^^^^^^
  File "C:\Users\zengo\AppData\Local\Programs\Python\Python311\Lib\site-packages\nbclient\client.py", line 705, in async_execute
    await self.async_execute_cell(
  File "C:\Users\zengo\AppData\Local\Programs\Python\Python311\Lib\site-packages\nbclient\client.py", line 1058, in async_execute_cell
    await self._check_raise_for_error(cell, cell_index, exec_reply)
  File "C:\Users\zengo\AppData\Local\Programs\Python\Python311\Lib\site-packages\nbclient\client.py", line 914, in _check_raise_for_error
    raise CellExecutionError.from_cell_and_msg(cell, exec_reply_content)
nbclient.exceptions.CellExecutionError: An error occurred while executing the following cell:
------------------
CA = x.loc['x','2019-12-31']
CL = x.loc['totalCurrentLiabilities','x']
print(x)
print(x)
------------------


[1;31m---------------------------------------------------------------------------[0m
[1;31mNameError[0m                                 Traceback (most recent call last)
Cell [1;32mIn[30], line 1[0m
[1;32m----> 1[0m CA [38;5;241m=[39m [43mx[49m[38;5;241m.[39mloc[[38;5;124m'[39m[38;5;124mx[39m[38;5;124m'[39m,[38;5;124m'[39m[38;5;124m2019-12-31[39m[38;5;124m'[39m]
[0;32m      2[0m CL [38;5;241m=[39m x[38;5;241m.[39mloc[[38;5;124m'[39m[38;5;124mtotalCurrentLiabilities[39m[38;5;124m'[39m,[38;5;124m'[39m[38;5;124mx[39m[38;5;124m'[39m]
[0;32m      3[0m [38;5;28mprint[39m(x)

[1;31mNameError[0m: name 'x' is not defined

